[1m[31mERROR   [0m asyncio:base_events.py:1758 Task exception was never retrieved
future: <Task finished name='Task-287' coro=<Connection.reconnect() done, defined at /home/ubuntu/actions-runner/_work/test-runners-2-is-arm64-postgresql-k8s-operator/test-runners-2-is-arm64-postgresql-k8s-operator/.tox/integration/lib/python3.10/site-packages/juju/client/connection.py:779> exception=OSError(9, 'Bad file descriptor')>
Traceback (most recent call last):
  File "/home/ubuntu/actions-runner/_work/test-runners-2-is-arm64-postgresql-k8s-operator/test-runners-2-is-arm64-postgresql-k8s-operator/.tox/integration/lib/python3.10/site-packages/juju/client/connection.py", line 788, in reconnect
    res = await connector(
  File "/home/ubuntu/actions-runner/_work/test-runners-2-is-arm64-postgresql-k8s-operator/test-runners-2-is-arm64-postgresql-k8s-operator/.tox/integration/lib/python3.10/site-packages/juju/client/connection.py", line 868, in _connect_with_login
    await self._connect(endpoints)
  File "/home/ubuntu/actions-runner/_work/test-runners-2-is-arm64-postgresql-k8s-operator/test-runners-2-is-arm64-postgresql-k8s-operator/.tox/integration/lib/python3.10/site-packages/juju/client/connection.py", line 817, in _connect
    result = await task
  File "/usr/lib/python3.10/asyncio/tasks.py", line 571, in _wait_for_one
    return f.result()  # May raise f.exception().
  File "/home/ubuntu/actions-runner/_work/test-runners-2-is-arm64-postgresql-k8s-operator/test-runners-2-is-arm64-postgresql-k8s-operator/.tox/integration/lib/python3.10/site-packages/juju/client/connection.py", line 806, in _try_endpoint
    return await self._open(endpoint, cacert)
  File "/home/ubuntu/actions-runner/_work/test-runners-2-is-arm64-postgresql-k8s-operator/test-runners-2-is-arm64-postgresql-k8s-operator/.tox/integration/lib/python3.10/site-packages/juju/client/connection.py", line 427, in _open
    return (await websockets.connect(
  File "/home/ubuntu/actions-runner/_work/test-runners-2-is-arm64-postgresql-k8s-operator/test-runners-2-is-arm64-postgresql-k8s-operator/.tox/integration/lib/python3.10/site-packages/websockets/legacy/client.py", line 647, in __await_impl_timeout__
    return await self.__await_impl__()
  File "/home/ubuntu/actions-runner/_work/test-runners-2-is-arm64-postgresql-k8s-operator/test-runners-2-is-arm64-postgresql-k8s-operator/.tox/integration/lib/python3.10/site-packages/websockets/legacy/client.py", line 651, in __await_impl__
    _transport, _protocol = await self._create_connection()
  File "/usr/lib/python3.10/asyncio/base_events.py", line 1103, in create_connection
    transport, protocol = await self._create_connection_transport(
  File "/usr/lib/python3.10/asyncio/base_events.py", line 1119, in _create_connection_transport
    sock.setblocking(False)
OSError: [Errno 9] Bad file descriptor
[1m[31mERROR   [0m asyncio:base_events.py:1758 Task exception was never retrieved
future: <Task finished name='Task-288' coro=<Connection.reconnect() done, defined at /home/ubuntu/actions-runner/_work/test-runners-2-is-arm64-postgresql-k8s-operator/test-runners-2-is-arm64-postgresql-k8s-operator/.tox/integration/lib/python3.10/site-packages/juju/client/connection.py:779> exception=OSError(9, 'Bad file descriptor')>
Traceback (most recent call last):
  File "/home/ubuntu/actions-runner/_work/test-runners-2-is-arm64-postgresql-k8s-operator/test-runners-2-is-arm64-postgresql-k8s-operator/.tox/integration/lib/python3.10/site-packages/juju/client/connection.py", line 788, in reconnect
    res = await connector(
  File "/home/ubuntu/actions-runner/_work/test-runners-2-is-arm64-postgresql-k8s-operator/test-runners-2-is-arm64-postgresql-k8s-operator/.tox/integration/lib/python3.10/site-packages/juju/client/connection.py", line 868, in _connect_with_login
    await self._connect(endpoints)
  File "/home/ubuntu/actions-runner/_work/test-runners-2-is-arm64-postgresql-k8s-operator/test-runners-2-is-arm64-postgresql-k8s-operator/.tox/integration/lib/python3.10/site-packages/juju/client/connection.py", line 817, in _connect
    result = await task
  File "/usr/lib/python3.10/asyncio/tasks.py", line 571, in _wait_for_one
    return f.result()  # May raise f.exception().
  File "/home/ubuntu/actions-runner/_work/test-runners-2-is-arm64-postgresql-k8s-operator/test-runners-2-is-arm64-postgresql-k8s-operator/.tox/integration/lib/python3.10/site-packages/juju/client/connection.py", line 806, in _try_endpoint
    return await self._open(endpoint, cacert)
  File "/home/ubuntu/actions-runner/_work/test-runners-2-is-arm64-postgresql-k8s-operator/test-runners-2-is-arm64-postgresql-k8s-operator/.tox/integration/lib/python3.10/site-packages/juju/client/connection.py", line 427, in _open
    return (await websockets.connect(
  File "/home/ubuntu/actions-runner/_work/test-runners-2-is-arm64-postgresql-k8s-operator/test-runners-2-is-arm64-postgresql-k8s-operator/.tox/integration/lib/python3.10/site-packages/websockets/legacy/client.py", line 647, in __await_impl_timeout__
    return await self.__await_impl__()
  File "/home/ubuntu/actions-runner/_work/test-runners-2-is-arm64-postgresql-k8s-operator/test-runners-2-is-arm64-postgresql-k8s-operator/.tox/integration/lib/python3.10/site-packages/websockets/legacy/client.py", line 651, in __await_impl__
    _transport, _protocol = await self._create_connection()
  File "/usr/lib/python3.10/asyncio/base_events.py", line 1103, in create_connection
    transport, protocol = await self._create_connection_transport(
  File "/usr/lib/python3.10/asyncio/base_events.py", line 1119, in _create_connection_transport
    sock.setblocking(False)
OSError: [Errno 9] Bad file descriptor
[32mINFO    [0m pytest_operator.plugin:plugin.py:862 Model status:

Model  Controller          Cloud/Region        Version  SLA          Timestamp
test   microk8s-localhost  microk8s/localhost  3.4.4    unsupported  01:45:55Z

App             Version  Status   Scale  Charm           Channel  Rev  Address         Exposed  Message
postgresql-k8s           waiting    0/3  postgresql-k8s             0  10.152.183.124  no       installing agent

Unit              Workload  Agent       Address  Ports  Message
postgresql-k8s/0  waiting   allocating                  installing agent
postgresql-k8s/1  waiting   allocating                  installing agent
postgresql-k8s/2  waiting   allocating                  installing agent

[32mINFO    [0m pytest_operator.plugin:plugin.py:868 Juju error logs:

controller-0: 01:45:08 ERROR juju.worker.caasapplicationprovisioner.runner exited "postgresql-k8s": refreshing application status for "postgresql-k8s": Get "https://10.152.183.1:443/apis/apps/v1/namespaces/test/statefulsets/postgresql-k8s": dial tcp 10.152.183.1:443: connect: connection refused
controller-0: 01:45:11 ERROR juju.worker.caasapplicationprovisioner.runner exited "postgresql-k8s": checking if "postgresql-k8s" has an operator pod due to upgrading the charm from a pod-spec charm to a sidecar charm: Get "https://10.152.183.1:443/apis/apps/v1/namespaces/test/statefulsets/postgresql-k8s-operator": dial tcp 10.152.183.1:443: connect: connection refused
controller-0: 01:45:16 ERROR juju.worker.caasapplicationprovisioner.runner exited "postgresql-k8s": checking if "postgresql-k8s" has an operator pod due to upgrading the charm from a pod-spec charm to a sidecar charm: Get "https://10.152.183.1:443/apis/apps/v1/namespaces/test/statefulsets/postgresql-k8s-operator": dial tcp 10.152.183.1:443: connect: connection refused
controller-0: 01:45:19 ERROR juju.worker.caasapplicationprovisioner.runner exited "postgresql-k8s": checking if "postgresql-k8s" has an operator pod due to upgrading the charm from a pod-spec charm to a sidecar charm: Get "https://10.152.183.1:443/apis/apps/v1/namespaces/test/statefulsets/postgresql-k8s-operator": dial tcp 10.152.183.1:443: connect: connection refused
controller-0: 01:45:23 ERROR juju.worker.caasapplicationprovisioner.runner exited "postgresql-k8s": checking if "postgresql-k8s" has an operator pod due to upgrading the charm from a pod-spec charm to a sidecar charm: Get "https://10.152.183.1:443/apis/apps/v1/namespaces/test/statefulsets/postgresql-k8s-operator": dial tcp 10.152.183.1:443: connect: connection refused
controller-0: 01:45:26 ERROR juju.worker.caasapplicationprovisioner.runner exited "postgresql-k8s": checking if "postgresql-k8s" has an operator pod due to upgrading the charm from a pod-spec charm to a sidecar charm: Get "https://10.152.183.1:443/apis/apps/v1/namespaces/test/statefulsets/postgresql-k8s-operator": dial tcp 10.152.183.1:443: connect: connection refused
controller-0: 01:45:29 ERROR juju.worker.caasapplicationprovisioner.runner exited "postgresql-k8s": checking if "postgresql-k8s" has an operator pod due to upgrading the charm from a pod-spec charm to a sidecar charm: Get "https://10.152.183.1:443/apis/apps/v1/namespaces/test/statefulsets/postgresql-k8s-operator": dial tcp 10.152.183.1:443: connect: connection refused
controller-0: 01:45:32 ERROR juju.worker.caasapplicationprovisioner.runner exited "postgresql-k8s": checking if "postgresql-k8s" has an operator pod due to upgrading the charm from a pod-spec charm to a sidecar charm: Get "https://10.152.183.1:443/apis/apps/v1/namespaces/test/statefulsets/postgresql-k8s-operator": dial tcp 10.152.183.1:443: connect: connection refused

[32mINFO    [0m pytest_operator.plugin:plugin.py:947 Forgetting model main...