[32mINFO    [0m pytest_operator.plugin:plugin.py:862 Model status:

Model  Controller          Cloud/Region        Version  SLA          Timestamp
test   microk8s-localhost  microk8s/localhost  3.1.8    unsupported  01:44:22Z

App                   Version  Status   Scale  Charm                Channel  Rev  Address         Exposed  Message
postgresql-k8s        14.11    waiting      3  postgresql-k8s                  0  10.152.183.29   no       installing agent
postgresql-test-app            waiting      1  postgresql-test-app  edge     159  10.152.183.83   no       installing agent
postgresql-test-app2           active       1  postgresql-test-app  edge     159  10.152.183.232  no       

Unit                     Workload     Agent      Address       Ports  Message
postgresql-k8s/0*        active       executing  10.1.126.139         Primary
postgresql-k8s/1         maintenance  executing  10.1.126.141         (start) 
postgresql-k8s/2         maintenance  executing  10.1.126.140         
postgresql-test-app2/0*  active       idle       10.1.126.143         
postgresql-test-app/0*   maintenance  executing  10.1.126.142         (start) 

[32mINFO    [0m pytest_operator.plugin:plugin.py:868 Juju error logs:

unit-postgresql-k8s-1: 01:33:58 ERROR unit.postgresql-k8s/1.juju-log failed to patch k8s Endpoints patroni-postgresql-k8s
Traceback (most recent call last):
  File "/var/lib/juju/agents/unit-postgresql-k8s-1/charm/venv/lightkube/core/generic_client.py", line 188, in raise_for_status
    resp.raise_for_status()
  File "/var/lib/juju/agents/unit-postgresql-k8s-1/charm/venv/httpx/_models.py", line 761, in raise_for_status
    raise HTTPStatusError(message, request=request, response=self)
httpx.HTTPStatusError: Client error '409 Conflict' for url 'https://10.152.183.1/api/v1/namespaces/test/endpoints/patroni-postgresql-k8s?force=true&fieldManager=postgresql-k8s'
For more information check: https://developer.mozilla.org/en-US/docs/Web/HTTP/Status/409

During handling of the above exception, another exception occurred:

Traceback (most recent call last):
  File "/var/lib/juju/agents/unit-postgresql-k8s-1/charm/./src/charm.py", line 1098, in _on_stop
    client.apply(
  File "/var/lib/juju/agents/unit-postgresql-k8s-1/charm/venv/lightkube/core/client.py", line 457, in apply
    return self.patch(type(obj), name, obj, namespace=namespace,
  File "/var/lib/juju/agents/unit-postgresql-k8s-1/charm/venv/lightkube/core/client.py", line 325, in patch
    return self._client.request("patch", res=res, name=name, namespace=namespace, obj=obj,
  File "/var/lib/juju/agents/unit-postgresql-k8s-1/charm/venv/lightkube/core/generic_client.py", line 245, in request
    return self.handle_response(method, resp, br)
  File "/var/lib/juju/agents/unit-postgresql-k8s-1/charm/venv/lightkube/core/generic_client.py", line 196, in handle_response
    self.raise_for_status(resp)
  File "/var/lib/juju/agents/unit-postgresql-k8s-1/charm/venv/lightkube/core/generic_client.py", line 190, in raise_for_status
    raise transform_exception(e)
lightkube.core.exceptions.ApiError: Operation cannot be fulfilled on endpoints "patroni-postgresql-k8s": the object has been modified; please apply your changes to the latest version and try again
unit-postgresql-k8s-1: 01:33:59 ERROR unit.postgresql-k8s/1.juju-log failed to patch k8s Endpoints patroni-postgresql-k8s-config
Traceback (most recent call last):
  File "/var/lib/juju/agents/unit-postgresql-k8s-1/charm/venv/lightkube/core/generic_client.py", line 188, in raise_for_status
    resp.raise_for_status()
  File "/var/lib/juju/agents/unit-postgresql-k8s-1/charm/venv/httpx/_models.py", line 761, in raise_for_status
    raise HTTPStatusError(message, request=request, response=self)
httpx.HTTPStatusError: Client error '409 Conflict' for url 'https://10.152.183.1/api/v1/namespaces/test/endpoints/patroni-postgresql-k8s-config?force=true&fieldManager=postgresql-k8s'
For more information check: https://developer.mozilla.org/en-US/docs/Web/HTTP/Status/409

During handling of the above exception, another exception occurred:

Traceback (most recent call last):
  File "/var/lib/juju/agents/unit-postgresql-k8s-1/charm/./src/charm.py", line 1098, in _on_stop
    client.apply(
  File "/var/lib/juju/agents/unit-postgresql-k8s-1/charm/venv/lightkube/core/client.py", line 457, in apply
    return self.patch(type(obj), name, obj, namespace=namespace,
  File "/var/lib/juju/agents/unit-postgresql-k8s-1/charm/venv/lightkube/core/client.py", line 325, in patch
    return self._client.request("patch", res=res, name=name, namespace=namespace, obj=obj,
  File "/var/lib/juju/agents/unit-postgresql-k8s-1/charm/venv/lightkube/core/generic_client.py", line 245, in request
    return self.handle_response(method, resp, br)
  File "/var/lib/juju/agents/unit-postgresql-k8s-1/charm/venv/lightkube/core/generic_client.py", line 196, in handle_response
    self.raise_for_status(resp)
  File "/var/lib/juju/agents/unit-postgresql-k8s-1/charm/venv/lightkube/core/generic_client.py", line 190, in raise_for_status
    raise transform_exception(e)
lightkube.core.exceptions.ApiError: Operation cannot be fulfilled on endpoints "patroni-postgresql-k8s-config": the object has been modified; please apply your changes to the latest version and try again
unit-postgresql-k8s-1: 01:33:59 ERROR unit.postgresql-k8s/1.juju-log failed to patch k8s Endpoints patroni-postgresql-k8s-sync
Traceback (most recent call last):
  File "/var/lib/juju/agents/unit-postgresql-k8s-1/charm/venv/lightkube/core/generic_client.py", line 188, in raise_for_status
    resp.raise_for_status()
  File "/var/lib/juju/agents/unit-postgresql-k8s-1/charm/venv/httpx/_models.py", line 761, in raise_for_status
    raise HTTPStatusError(message, request=request, response=self)
httpx.HTTPStatusError: Client error '409 Conflict' for url 'https://10.152.183.1/api/v1/namespaces/test/endpoints/patroni-postgresql-k8s-sync?force=true&fieldManager=postgresql-k8s'
For more information check: https://developer.mozilla.org/en-US/docs/Web/HTTP/Status/409

During handling of the above exception, another exception occurred:

Traceback (most recent call last):
  File "/var/lib/juju/agents/unit-postgresql-k8s-1/charm/./src/charm.py", line 1098, in _on_stop
    client.apply(
  File "/var/lib/juju/agents/unit-postgresql-k8s-1/charm/venv/lightkube/core/client.py", line 457, in apply
    return self.patch(type(obj), name, obj, namespace=namespace,
  File "/var/lib/juju/agents/unit-postgresql-k8s-1/charm/venv/lightkube/core/client.py", line 325, in patch
    return self._client.request("patch", res=res, name=name, namespace=namespace, obj=obj,
  File "/var/lib/juju/agents/unit-postgresql-k8s-1/charm/venv/lightkube/core/generic_client.py", line 245, in request
    return self.handle_response(method, resp, br)
  File "/var/lib/juju/agents/unit-postgresql-k8s-1/charm/venv/lightkube/core/generic_client.py", line 196, in handle_response
    self.raise_for_status(resp)
  File "/var/lib/juju/agents/unit-postgresql-k8s-1/charm/venv/lightkube/core/generic_client.py", line 190, in raise_for_status
    raise transform_exception(e)
lightkube.core.exceptions.ApiError: Operation cannot be fulfilled on endpoints "patroni-postgresql-k8s-sync": the object has been modified; please apply your changes to the latest version and try again
unit-postgresql-k8s-1: 01:33:59 ERROR unit.postgresql-k8s/1.juju-log failed to patch k8s Endpoints postgresql-k8s
Traceback (most recent call last):
  File "/var/lib/juju/agents/unit-postgresql-k8s-1/charm/venv/lightkube/core/generic_client.py", line 188, in raise_for_status
    resp.raise_for_status()
  File "/var/lib/juju/agents/unit-postgresql-k8s-1/charm/venv/httpx/_models.py", line 761, in raise_for_status
    raise HTTPStatusError(message, request=request, response=self)
httpx.HTTPStatusError: Client error '409 Conflict' for url 'https://10.152.183.1/api/v1/namespaces/test/endpoints/postgresql-k8s?force=true&fieldManager=postgresql-k8s'
For more information check: https://developer.mozilla.org/en-US/docs/Web/HTTP/Status/409

During handling of the above exception, another exception occurred:

Traceback (most recent call last):
  File "/var/lib/juju/agents/unit-postgresql-k8s-1/charm/./src/charm.py", line 1098, in _on_stop
    client.apply(
  File "/var/lib/juju/agents/unit-postgresql-k8s-1/charm/venv/lightkube/core/client.py", line 457, in apply
    return self.patch(type(obj), name, obj, namespace=namespace,
  File "/var/lib/juju/agents/unit-postgresql-k8s-1/charm/venv/lightkube/core/client.py", line 325, in patch
    return self._client.request("patch", res=res, name=name, namespace=namespace, obj=obj,
  File "/var/lib/juju/agents/unit-postgresql-k8s-1/charm/venv/lightkube/core/generic_client.py", line 245, in request
    return self.handle_response(method, resp, br)
  File "/var/lib/juju/agents/unit-postgresql-k8s-1/charm/venv/lightkube/core/generic_client.py", line 196, in handle_response
    self.raise_for_status(resp)
  File "/var/lib/juju/agents/unit-postgresql-k8s-1/charm/venv/lightkube/core/generic_client.py", line 190, in raise_for_status
    raise transform_exception(e)
lightkube.core.exceptions.ApiError: Operation cannot be fulfilled on endpoints "postgresql-k8s": the object has been modified; please apply your changes to the latest version and try again
unit-postgresql-k8s-1: 01:33:59 ERROR unit.postgresql-k8s/1.juju-log failed to patch k8s Endpoints postgresql-k8s-primary
Traceback (most recent call last):
  File "/var/lib/juju/agents/unit-postgresql-k8s-1/charm/venv/lightkube/core/generic_client.py", line 188, in raise_for_status
    resp.raise_for_status()
  File "/var/lib/juju/agents/unit-postgresql-k8s-1/charm/venv/httpx/_models.py", line 761, in raise_for_status
    raise HTTPStatusError(message, request=request, response=self)
httpx.HTTPStatusError: Client error '409 Conflict' for url 'https://10.152.183.1/api/v1/namespaces/test/endpoints/postgresql-k8s-primary?force=true&fieldManager=postgresql-k8s'
For more information check: https://developer.mozilla.org/en-US/docs/Web/HTTP/Status/409

During handling of the above exception, another exception occurred:

Traceback (most recent call last):
  File "/var/lib/juju/agents/unit-postgresql-k8s-1/charm/./src/charm.py", line 1098, in _on_stop
    client.apply(
  File "/var/lib/juju/agents/unit-postgresql-k8s-1/charm/venv/lightkube/core/client.py", line 457, in apply
    return self.patch(type(obj), name, obj, namespace=namespace,
  File "/var/lib/juju/agents/unit-postgresql-k8s-1/charm/venv/lightkube/core/client.py", line 325, in patch
    return self._client.request("patch", res=res, name=name, namespace=namespace, obj=obj,
  File "/var/lib/juju/agents/unit-postgresql-k8s-1/charm/venv/lightkube/core/generic_client.py", line 245, in request
    return self.handle_response(method, resp, br)
  File "/var/lib/juju/agents/unit-postgresql-k8s-1/charm/venv/lightkube/core/generic_client.py", line 196, in handle_response
    self.raise_for_status(resp)
  File "/var/lib/juju/agents/unit-postgresql-k8s-1/charm/venv/lightkube/core/generic_client.py", line 190, in raise_for_status
    raise transform_exception(e)
lightkube.core.exceptions.ApiError: Operation cannot be fulfilled on endpoints "postgresql-k8s-primary": the object has been modified; please apply your changes to the latest version and try again
unit-postgresql-k8s-1: 01:33:59 ERROR unit.postgresql-k8s/1.juju-log failed to patch k8s Endpoints postgresql-k8s-replicas
Traceback (most recent call last):
  File "/var/lib/juju/agents/unit-postgresql-k8s-1/charm/venv/lightkube/core/generic_client.py", line 188, in raise_for_status
    resp.raise_for_status()
  File "/var/lib/juju/agents/unit-postgresql-k8s-1/charm/venv/httpx/_models.py", line 761, in raise_for_status
    raise HTTPStatusError(message, request=request, response=self)
httpx.HTTPStatusError: Client error '409 Conflict' for url 'https://10.152.183.1/api/v1/namespaces/test/endpoints/postgresql-k8s-replicas?force=true&fieldManager=postgresql-k8s'
For more information check: https://developer.mozilla.org/en-US/docs/Web/HTTP/Status/409

During handling of the above exception, another exception occurred:

Traceback (most recent call last):
  File "/var/lib/juju/agents/unit-postgresql-k8s-1/charm/./src/charm.py", line 1098, in _on_stop
    client.apply(
  File "/var/lib/juju/agents/unit-postgresql-k8s-1/charm/venv/lightkube/core/client.py", line 457, in apply
    return self.patch(type(obj), name, obj, namespace=namespace,
  File "/var/lib/juju/agents/unit-postgresql-k8s-1/charm/venv/lightkube/core/client.py", line 325, in patch
    return self._client.request("patch", res=res, name=name, namespace=namespace, obj=obj,
  File "/var/lib/juju/agents/unit-postgresql-k8s-1/charm/venv/lightkube/core/generic_client.py", line 245, in request
    return self.handle_response(method, resp, br)
  File "/var/lib/juju/agents/unit-postgresql-k8s-1/charm/venv/lightkube/core/generic_client.py", line 196, in handle_response
    self.raise_for_status(resp)
  File "/var/lib/juju/agents/unit-postgresql-k8s-1/charm/venv/lightkube/core/generic_client.py", line 190, in raise_for_status
    raise transform_exception(e)
lightkube.core.exceptions.ApiError: Operation cannot be fulfilled on endpoints "postgresql-k8s-replicas": the object has been modified; please apply your changes to the latest version and try again
unit-postgresql-k8s-1: 01:33:59 ERROR unit.postgresql-k8s/1.juju-log failed to patch k8s Service patroni-postgresql-k8s-config
Traceback (most recent call last):
  File "/var/lib/juju/agents/unit-postgresql-k8s-1/charm/venv/lightkube/core/generic_client.py", line 188, in raise_for_status
    resp.raise_for_status()
  File "/var/lib/juju/agents/unit-postgresql-k8s-1/charm/venv/httpx/_models.py", line 761, in raise_for_status
    raise HTTPStatusError(message, request=request, response=self)
httpx.HTTPStatusError: Client error '409 Conflict' for url 'https://10.152.183.1/api/v1/namespaces/test/services/patroni-postgresql-k8s-config?force=true&fieldManager=postgresql-k8s'
For more information check: https://developer.mozilla.org/en-US/docs/Web/HTTP/Status/409

During handling of the above exception, another exception occurred:

Traceback (most recent call last):
  File "/var/lib/juju/agents/unit-postgresql-k8s-1/charm/./src/charm.py", line 1098, in _on_stop
    client.apply(
  File "/var/lib/juju/agents/unit-postgresql-k8s-1/charm/venv/lightkube/core/client.py", line 457, in apply
    return self.patch(type(obj), name, obj, namespace=namespace,
  File "/var/lib/juju/agents/unit-postgresql-k8s-1/charm/venv/lightkube/core/client.py", line 325, in patch
    return self._client.request("patch", res=res, name=name, namespace=namespace, obj=obj,
  File "/var/lib/juju/agents/unit-postgresql-k8s-1/charm/venv/lightkube/core/generic_client.py", line 245, in request
    return self.handle_response(method, resp, br)
  File "/var/lib/juju/agents/unit-postgresql-k8s-1/charm/venv/lightkube/core/generic_client.py", line 196, in handle_response
    self.raise_for_status(resp)
  File "/var/lib/juju/agents/unit-postgresql-k8s-1/charm/venv/lightkube/core/generic_client.py", line 190, in raise_for_status
    raise transform_exception(e)
lightkube.core.exceptions.ApiError: Operation cannot be fulfilled on services "patroni-postgresql-k8s-config": the object has been modified; please apply your changes to the latest version and try again
unit-postgresql-k8s-2: 01:37:30 ERROR unit.postgresql-k8s/2.juju-log failed to change plugins: 
Traceback (most recent call last):
  File "/var/lib/juju/agents/unit-postgresql-k8s-2/charm/lib/charms/postgresql_k8s/v0/postgresql.py", line 301, in enable_disable_extensions
    with self._connect_to_database() as connection, connection.cursor() as cursor:
  File "/var/lib/juju/agents/unit-postgresql-k8s-2/charm/lib/charms/postgresql_k8s/v0/postgresql.py", line 128, in _connect_to_database
    connection = psycopg2.connect(
  File "/var/lib/juju/agents/unit-postgresql-k8s-2/charm/venv/psycopg2/__init__.py", line 122, in connect
    conn = _connect(dsn, connection_factory=connection_factory, **kwasync)
psycopg2.OperationalError: connection to server at "postgresql-k8s-primary.test.svc.cluster.local" (10.152.183.119), port 5432 failed: Connection refused
	Is the server running on that host and accepting TCP/IP connections?


During handling of the above exception, another exception occurred:

Traceback (most recent call last):
  File "/var/lib/juju/agents/unit-postgresql-k8s-2/charm/./src/charm.py", line 546, in enable_disable_extensions
    self.postgresql.enable_disable_extensions(extensions, database)
  File "/var/lib/juju/agents/unit-postgresql-k8s-2/charm/lib/charms/postgresql_k8s/v0/postgresql.py", line 325, in enable_disable_extensions
    raise PostgreSQLEnableDisableExtensionError()
charms.postgresql_k8s.v0.postgresql.PostgreSQLEnableDisableExtensionError
unit-postgresql-k8s-0: 01:38:09 ERROR juju.worker.uniter pebble poll failed for container "postgresql": failed to send pebble-ready event: terminated
unit-postgresql-k8s-2: 01:39:06 ERROR unit.postgresql-k8s/2.juju-log failed to change plugins: 
Traceback (most recent call last):
  File "/var/lib/juju/agents/unit-postgresql-k8s-2/charm/lib/charms/postgresql_k8s/v0/postgresql.py", line 301, in enable_disable_extensions
    with self._connect_to_database() as connection, connection.cursor() as cursor:
  File "/var/lib/juju/agents/unit-postgresql-k8s-2/charm/lib/charms/postgresql_k8s/v0/postgresql.py", line 128, in _connect_to_database
    connection = psycopg2.connect(
  File "/var/lib/juju/agents/unit-postgresql-k8s-2/charm/venv/psycopg2/__init__.py", line 122, in connect
    conn = _connect(dsn, connection_factory=connection_factory, **kwasync)
psycopg2.OperationalError: connection to server at "postgresql-k8s-primary.test.svc.cluster.local" (10.152.183.119), port 5432 failed: Connection refused
	Is the server running on that host and accepting TCP/IP connections?


During handling of the above exception, another exception occurred:

Traceback (most recent call last):
  File "/var/lib/juju/agents/unit-postgresql-k8s-2/charm/./src/charm.py", line 546, in enable_disable_extensions
    self.postgresql.enable_disable_extensions(extensions, database)
  File "/var/lib/juju/agents/unit-postgresql-k8s-2/charm/lib/charms/postgresql_k8s/v0/postgresql.py", line 325, in enable_disable_extensions
    raise PostgreSQLEnableDisableExtensionError()
charms.postgresql_k8s.v0.postgresql.PostgreSQLEnableDisableExtensionError
controller-0: 01:41:14 ERROR juju.worker.caasapplicationprovisioner.runner exited "postgresql-test-app2": more than 20 retries ensuring trust: updating application "postgresql-test-app2" to desired trust false: getting service account role "postgresql-test-app2": k8s: roles.rbac.authorization.k8s.io "postgresql-test-app2" not found
unit-postgresql-k8s-0: 01:42:13 ERROR unit.postgresql-k8s/0.juju-log db:6: ERROR - `extensions` (unaccent, pg_trgm) cannot be requested through relations - Please enable extensions through `juju config` and add the relation again.
unit-postgresql-k8s-2: 01:44:13 ERROR unit.postgresql-k8s/2.juju-log Uncaught exception while in charm code:
Traceback (most recent call last):
  File "/var/lib/juju/agents/unit-postgresql-k8s-2/charm/./src/charm.py", line 1691, in <module>
    main(PostgresqlOperatorCharm, use_juju_for_storage=True)
  File "/var/lib/juju/agents/unit-postgresql-k8s-2/charm/venv/ops/main.py", line 544, in main
    manager.run()
  File "/var/lib/juju/agents/unit-postgresql-k8s-2/charm/venv/ops/main.py", line 520, in run
    self._emit()
  File "/var/lib/juju/agents/unit-postgresql-k8s-2/charm/venv/ops/main.py", line 509, in _emit
    _emit_charm_event(self.charm, self.dispatcher.event_name)
  File "/var/lib/juju/agents/unit-postgresql-k8s-2/charm/venv/ops/main.py", line 143, in _emit_charm_event
    event_to_emit.emit(*args, **kwargs)
  File "/var/lib/juju/agents/unit-postgresql-k8s-2/charm/venv/ops/framework.py", line 352, in emit
    framework._emit(event)
  File "/var/lib/juju/agents/unit-postgresql-k8s-2/charm/venv/ops/framework.py", line 851, in _emit
    self._reemit(event_path)
  File "/var/lib/juju/agents/unit-postgresql-k8s-2/charm/venv/ops/framework.py", line 941, in _reemit
    custom_handler(event)
  File "/var/lib/juju/agents/unit-postgresql-k8s-2/charm/./src/charm.py", line 475, in _on_config_changed
    self.update_config()
  File "/var/lib/juju/agents/unit-postgresql-k8s-2/charm/./src/charm.py", line 1512, in update_config
    current_layer = container.get_plan()
  File "/var/lib/juju/agents/unit-postgresql-k8s-2/charm/venv/ops/model.py", line 2186, in get_plan
    return self._pebble.get_plan()
  File "/var/lib/juju/agents/unit-postgresql-k8s-2/charm/venv/ops/pebble.py", line 2113, in get_plan
    resp = self._request('GET', '/v1/plan', {'format': 'yaml'})
  File "/var/lib/juju/agents/unit-postgresql-k8s-2/charm/venv/ops/pebble.py", line 1778, in _request
    response = self._request_raw(method, path, query, headers, data)
  File "/var/lib/juju/agents/unit-postgresql-k8s-2/charm/venv/ops/pebble.py", line 1827, in _request_raw
    raise ConnectionError(
ops.pebble.ConnectionError: Could not connect to Pebble: socket not found at '/charm/containers/postgresql/pebble.socket' (container restarted?)
unit-postgresql-k8s-2: 01:44:14 ERROR juju.worker.uniter.operation hook "config-changed" (via hook dispatching script: dispatch) failed: exit status 1

[32mINFO    [0m pytest_operator.plugin:plugin.py:947 Forgetting model main...